Workbook

Sheet 表紙
A1: 【表紙】 | K1: 顧客名 / プロジェクト名 | V1: システム名 / サブシステム名 | AG1: 機能ID / 機能名
K2: BQ | V2: 受講管理システム | AG2: BJ990100E
K3: BJ | V3: マスタメンテナンス | AG3: ログインユーザマスタ管理
B5: 仕様書構成
B6: No | E6: 設計区分 | K6: 名称 | AF6: 備考
B7: =ROW()-6 -> 1 | E7: － | K7: 表紙
B8: =ROW()-6 -> 2 | E8: － | K8: 改版履歴
B9: =ROW()-6 -> 3 | E9: 概要設計 | K9: 機能概要、システムフロー図
B10: =ROW()-6 -> 4 | E10: 概要設計 | K10: 画面レイアウト
B11: =ROW()-6 -> 5 | E11: 概要設計 | K11: 項目仕様
B12: =ROW()-6 -> 6 | E12: 詳細設計 | K12: イベント仕様

Sheet 改版履歴
A1: 【改版履歴】 | K1: 顧客名 / プロジェクト名 | V1: システム名 / サブシステム名 | AG1: 機能ID / 機能名
K2: =表紙!K2 -> BQ | V2: =表紙!V2 -> 受講管理システム | AG2: =表紙!AG2 -> BJ990100E
K3: =表紙!K3 -> BJ | V3: =表紙!V3 -> マスタメンテナンス | AG3: =表紙!AG3 -> ログインユーザマスタ管理
A5: No | C5: 更新日 | H5: 担当者 | K5: リリース日 | O5: 変更内容
A6: =ROW()-5 -> 1 | C6: 45992 | H6: 金田 | K6: - | O6: 新規作成
A7: =ROW()-5 -> 2
A8: =ROW()-5 -> 3
A9: =ROW()-5 -> 4
A10: =ROW()-5 -> 5
A11: =ROW()-5 -> 6
A12: =ROW()-5 -> 7
A13: =ROW()-5 -> 8
A14: =ROW()-5 -> 9
A15: =ROW()-5 -> 10
A16: =ROW()-5 -> 11
A17: =ROW()-5 -> 12
A18: =ROW()-5 -> 13
... A39: =ROW()-5 -> 34

Sheet 機能概要
A1: 【機能概要】 | K1: 顧客名 / プロジェクト名 | V1: システム名 / サブシステム名 | AG1: 機能ID / 機能名
K2: =表紙!K2 -> BQ | V2: =表紙!V2 -> 受講管理システム | AG2: =表紙!AG2 -> BJ990100E
K3: =表紙!K3 -> BJ | V3: =表紙!V3 -> マスタメンテナンス | AG3: =表紙!AG3 -> ログインユーザマスタ管理
A5: ■機能概要
B6: ・ログインユーザの管理やパスワードの管理を行う画面
A9: ■システムフロー図
F12: 参照テーブル | L12: CRUD | AI12: 更新テーブル | AO12: CRUD
D13: 方面担当マスタ | L13: R | AG13: ログインマスタ | AO13: CRU
D14: 定数マスタ | L14: R
T16: ログインユーザマスタ管理
O25: 出力テーブル | U25: CRUD | AA25: 帳票／出力ファイル | AG25: 種類
AP29: Ｃ：CREATE（新規） Ｒ：READ（参照） Ｕ：UPDATE（更新） Ｄ：DELETE（削除）

Sheet 画面レイアウト
A1: 【画面レイアウト】 | K1: 顧客名 / プロジェクト名 | V1: システム名 / サブシステム名 | AG1: 機能ID / 機能名
K2: =表紙!K2 -> BQ | V2: =表紙!V2 -> 受講管理システム | AG2: =表紙!AG2 -> BJ990100E
K3: =表紙!K3 -> BJ | V3: =表紙!V3 -> マスタメンテナンス | AG3: =表紙!AG3 -> ログインユーザマスタ管理
AQ5: ■仕様補足説明
AQ7: ※新規作成ボタン
AQ8: 明細情報を初期表示し、
AQ9: ログイン情報入力後、登録
AQ10: ボタン押下でDB登録する
AQ12: ※修正
AQ13: ・一覧の行をダブルクリック
AQ14: することにより対応する明細
AQ15: 情報を表示し修正可能とする
AQ17: ※無効を含む
AR18: チェックされた場合、無効
AR19: データを一覧表示対象と
AR20: する
AQ22: ※ログイン情報
AQ23: ・パスワードチェック
AQ24: 8桁以上のチェックを行う
AQ25: 英数字、記号の混在チェック
AQ26: は行わない
AQ28: ・無効チェックをチェック
AQ29: した場合、該当のログインID
AQ30: は無効IDとする
AQ33: ※登録・更新ボタン
AQ34: ログイン情報一覧を選択した
AR35: 場合、「更新」で表示する
AQ36: 新規作成ボタンを押下した
AR37: 場合、「登録」で表示する

Sheet 項目仕様
A1: 【項目仕様】 | K1: 顧客名 / プロジェクト名 | V1: システム名 / サブシステム名 | AG1: 機能ID / 機能名 | BD1: 合計項目数 | BE1: 初回合格数 | BF1: 初回不合格数 | BG1: 未処理数
K2: =表紙!K2 -> BQ | V2: =表紙!V2 -> 受講管理システム | AG2: =表紙!AG2 -> BJ990100E | BD2: =COUNTA(BB6:BB65330) -> 0 | BE2: =COUNTIF(BF6:BF65330,"○") -> 0 | BF2: =COUNTIF(BF6:BF65330,"×*") -> 0 | BG2: =BD2 - COUNTIF(BG6:BG65330,">=1900/1/1") -> 0
K3: =表紙!K3 -> BJ | V3: =表紙!V3 -> マスタメンテナンス | AG3: =表紙!AG3 -> ログインユーザマスタ管理
A5: № | C5: 項目名 | M5: 型 | Q5: I/O | S5: 必須 | U5: 桁数 | W5: 書式 | AD5: 値の参照元 | AK5: 説明 | BA5: № | BB5: 四象限 | BC5: 補足 | BD5: 試験日 | BE5: 試験者 | BF5: 合否 | BG5: 完了日付
A6: =ROW()-5 -> 1 | C6: =AG3&"画面" -> ログインユーザマスタ管理画面 | U6: =IF(OR(M6="ラジオボタン",M6="ボタン",M6="スプレッド",M6="選択"),"-","") | W6: ・画面中央 | BA6: =IF(BB6&BC6<>"",MAX(BA$5:BA5)+1,"")
A7: =A6+1 -> 2 | C7: 戻る | M7: ボタン | Q7: I/O | U7: - | W7: 中央揃え | AK7: メインメニューへ遷移する
A8: =A7+1 -> 3 | C8: 無効を含む | M8: チェック | Q8: I | U8: - | W8: ・中央揃え | AK8: 表示対象にログインマスタ.無効フラグ＝1の情報を含むか否か 初期値：False | BA8: =IF(BB8&BC8<>"",MAX(BA$5:BA6)+1,"")
A9: =A8+1 -> 4 | C9: 【ログイン情報一覧】 | BA9: =IF(BB9&BC9<>"",MAX(#REF!)+1,"")
A10: =A9+1 -> 5 | C10: 方面担当 | M10: 選択 | Q10: O | U10: 20 | W10: ・左寄せ | AD10: 方面担当マスタ 方面担当名称
A11: =A10+1 -> 6 | C11: ログイン名 | M11: テキスト | Q11: O | U11: 40 | W11: ・左寄せ | AD11: ログインマスタ ログイン名
A12: =A11+1 -> 7 | C12: 権限区分 | M12: 選択 | Q12: O | U12: 20 | W12: ・左寄せ | AD12: 定数マスタ MCONST | AK12: （ログインマスタ.権限区分） 1：システム管理者、2：協会本部、3：方面本部
A13: =A12+1 -> 8 | C13: ログインID | M13: テキスト | Q13: O | U13: 20 | W13: ・左寄せ | AD13: ログインマスタ ログインID
A14: =A13+1 -> 9 | C14: パスワード | M14: テキスト | Q14: O | U14: 20 | W14: ・左寄せ、非表示列 | AD14: ログインマスタ パスワード
A15: =A14+1 -> 10 | C15: パスワード変更日 | M15: 日付 | Q15: O | U15: 8 | W15: ・中央揃え | AD15: ログインマスタ パスワード変更日
A16: =A15+1 -> 11 | C16: 有効期限 | M16: 日付 | Q16: O | U16: 8 | W16: ・中央揃え | AD16: 定数マスタ MCONST | AK16: 定数マスタ.有効期限日数＋パスワード変更日で設定する
A17: =A16+1 -> 12 | C17: 【ログイン情報】 | BA17: =IF(BB17&BC17<>"",MAX(BA$5:BA8)+1,"")
A18: =A17+1 -> 13 | C18: 新規作成 | M18: ボタン | Q18: I/O | U18: - | W18: 中央揃え | AK18: ログイン情報を初期表示する
A19: =A18+1 -> 14 | C19: 方面担当 | M19: 選択 | Q19: I/O | U19: 20 | W19: ・左寄せ | AD19: 方面担当マスタ 方面担当名称 | AK19: 初期値：フォーカス行の方面IDに紐づく方面担当名称 （新規作成時は空白）
A20: =A19+1 -> 15 | C20: ログイン名 | M20: テキスト | Q20: I/O | U20: 40 | W20: ・左寄せ | AK20: 初期値：フォーカス行のログイン名 （新規作成時は空白）
A21: =A20+1 -> 16 | C21: 権限区分 | M21: 選択 | Q21: I/O | U21: 20 | W21: ・左寄せ | AD21: 定数マスタ MCONST | AK21: 初期値：フォーカス行の権限区分名称 （新規作成時は空白）
A22: =A21+1 -> 17 | C22: ログインID | M22: テキスト | Q22: I/O | U22: 20 | W22: ・左寄せ | AK22: 初期値：フォーカス行のログインID （新規作成時は空白）
A23: =A22+1 -> 18 | C23: パスワード | M23: テキスト | Q23: I/O | U23: 20 | W23: ・左寄せ | AK23: 文字数が8桁以上であることをチェックする 初期値：フォーカス行のパスワード ●にてパスワード表示は行わない（新規作成時は空白）
A24: =A23+1 -> 19 | C24: パスワード変更日 | M24: 日付 | Q24: I/O | U24: 8 | W24: 中央揃え | AK24: 初期値：フォーカス行のパスワード変更日 （新規作成時は空白）
A25: =A24+1 -> 20 | C25: 有効期限 | M25: 日付 | Q25: I/O | U25: 8 | W25: 中央揃え | AK25: 初期値：フォーカス行の有効期限 （新規作成時は空白）
A26: =A25+1 -> 21 | C26: 有効無効フラグ | M26: チェック | Q26: I/O | U26: 1 | W26: 中央揃え | AK26: 初期値：フォーカス行の無効フラグ （新規作成時はチェックなし）
A27: =A26+1 -> 22 | C27: 【機能ボタン】
C28: 閉じる | M28: ボタン | Q28: I/O | U28: - | W28: 中央揃え | AK28: 画面を閉じる
A29: =A27+1 -> 23 | C29: 登録・更新 | M29: ボタン | Q29: I/O | U29: - | W29: 中央揃え | AK29: ログインユーザマスタを登録、更新する ログイン情報一覧を選択した場合、「更新」で表示する 新規作成ボタンを押下した場合、「登録」で表示する
U31: =IF(OR(M31="ラジオボタン",M31="ボタン",M31="スプレッド",M31="選択"),"-","") | BA31: =IF(BB31&BC31<>"",MAX(BA$5:BA30)+1,"")

Sheet イベント仕様
A1: 【イベント仕様】 | K1: 顧客名 / プロジェクト名 | V1: システム名 / サブシステム名 | AG1: 機能ID / 機能名 | BD1: 合計項目数 | BE1: 初回合格数 | BF1: 初回不合格数 | BG1: 未処理数
K2: =表紙!K2 -> BQ | V2: =表紙!V2 -> 受講管理システム | AG2: =表紙!AG2 -> BJ990100E | BD2: =COUNTA(BB6:BB183) -> 49 | BE2: =COUNTIF(BF6:BF183,"○") -> 0 | BF2: =COUNTIF(BF6:BF183,"×*") -> 0 | BG2: =BD2 - COUNTIF(BG6:BG183,">=1900/1/1") -> 49
K3: =表紙!K3 -> BJ | V3: =表紙!V3 -> マスタメンテナンス | AG3: =表紙!AG3 -> ログインユーザマスタ管理
A5: № | C5: 項目名/オブジェクト名 | L5: イベント名 | U5: 説明 | BA5: № | BB5: 四象限 | BC5: 補足 | BD5: 試験日 | BE5: 試験者 | BF5: 合否 | BG5: 完了日付
A6: 1 | C6: =IF(A6<>"",VLOOKUP(A6,項目仕様!$A$6:$L$129,3),"") -> ログインユーザマスタ管理画面 | L6: 画面ロード時処理 | U6: 1 | W6: 初期値表示処理 | BA6: =IF(BB6&BC6<>"",MAX(BA$5:BA5)+1,"")
C7: =IF(A7<>"",VLOOKUP(A7,項目仕様!$A$6:$L$129,3),"") | V7: 1.1 | X7: 各コンボボックスを作成する | AE7: ・・・画面ロード直後は選択不可、ログイン情報一覧のセルをクリック、 | BA7: =IF(BB7&BC7<>"",MAX(BA$5:BA6)+1,"")
C8: =IF(A8<>"",VLOOKUP(A8,項目仕様!$A$6:$L$129,3),"") | AF8: または新規作成ボタン押下で選択可に | BA8: =IF(BB8&BC8<>"",MAX(BA$5:BA7)+1,"")
C9: =IF(A9<>"",VLOOKUP(A9,項目仕様!$A$6:$L$129,3),"") | X9: ・方面担当 | BA9: =IF(BB9&BC9<>"",MAX(BA$5:BA8)+1,"")
C10: =IF(A10<>"",VLOOKUP(A10,項目仕様!$A$6:$L$129,3),"") | Y10: [リスト] | AF10: 方面マスタから取得（共通ルーチン）（共通DM） | BA10: =IF(BB10&BC10<>"",MAX(BA$5:BA9)+1,"") -> 1 | BB10: 正・単
C11: =IF(A11<>"",VLOOKUP(A11,項目仕様!$A$6:$L$129,3),"") | Y11: 方面担当 | AC11: ▼ | AF11: 削除フラグ='1'データは対象外 | BA11: =IF(BB11&BC11<>"",MAX(BA$5:BA10)+1,"")
C12: =IF(A12<>"",VLOOKUP(A12,項目仕様!$A$6:$L$129,3),"") | Y12: 方面担当略称 | AF12: 方面ID :非表示 | BA12: =IF(BB12&BC12<>"",MAX(BA$5:BA11)+1,"")
C13: =IF(A13<>"",VLOOKUP(A13,項目仕様!$A$6:$L$129,3),"") | BA13: =IF(BB13&BC13<>"",MAX(BA$5:BA12)+1,"")
C14: =IF(A14<>"",VLOOKUP(A14,項目仕様!$A$6:$L$129,3),"") | X14: ・権限区分 | BA14: =IF(BB14&BC14<>"",MAX(BA$5:BA13)+1,"")
C15: =IF(A15<>"",VLOOKUP(A15,項目仕様!$A$6:$L$129,3),"") | Y15: [リスト] | AF15: コンスタントマスタから取得（共通ルーチン）定数マスタから取得（共通DM） | BA15: =IF(BB15&BC15<>"",MAX(BA$5:BA14)+1,"") -> 2 | BB15: 正・単
C16: =IF(A16<>"",VLOOKUP(A16,項目仕様!$A$6:$L$129,3),"") | Y16: 権限区分 | AC16: ▼ | AF16: 削除フラグ='1'データは対象外 | BA16: =IF(BB16&BC16<>"",MAX(BA$5:BA15)+1,"")
C17: =IF(A17<>"",VLOOKUP(A17,項目仕様!$A$6:$L$129,3),"") | Y17: 権限区分名 | AF17: 権限区分：非表示 | BA17: =IF(BB17&BC17<>"",MAX(BA$5:BA16)+1,"")
C18: =IF(A18<>"",VLOOKUP(A18,項目仕様!$A$6:$L$129,3),"") | BA18: =IF(BB18&BC18<>"",MAX(BA$5:BA17)+1,"")
C19: =IF(A19<>"",VLOOKUP(A19,項目仕様!$A$6:$L$129,3),"") | V19: 1.2 | X19: 画面項目をクリアし、初期値を設定する ・・・画面ロード直後は空白、入力不可 | BA19: =IF(BB19&BC19<>"",MAX(BA$5:BA18)+1,"") -> 3 | BB19: 正・単
C20: =IF(A20<>"",VLOOKUP(A20,項目仕様!$A$6:$L$129,3),"") | BA20: =IF(BB20&BC20<>"",MAX(BA$5:BA19)+1,"")
C21: =IF(A21<>"",VLOOKUP(A21,項目仕様!$A$6:$L$129,3),"") | BA21: =IF(BB21&BC21<>"",MAX(BA$5:BA20)+1,"")
C22: =IF(A22<>"",VLOOKUP(A22,項目仕様!$A$6:$L$129,3),"") | U22: 2 | W22: ログインマスタ情報の一覧表示 | BA22: =IF(BB22&BC22<>"",MAX(BA$5:BA21)+1,"")
C23: =IF(A23<>"",VLOOKUP(A23,項目仕様!$A$6:$L$129,3),"") | V23: 2.1 | X23: ログインユーザ情報をログインユーザマスタから取得し、ログインユーザ情報一覧にセットする | AX23: SQLID： | AY23: S1 | BA23: =IF(BB23&BC23<>"",MAX(BA$5:BA22)+1,"") -> 4 | BB23: 正・単
C24: =IF(A24<>"",VLOOKUP(A24,項目仕様!$A$6:$L$129,3),"") | Y24: 引数.無効を含む＝False | BA24: =IF(BB24&BC24<>"",MAX(BA$5:BA23)+1,"")
C25: =IF(A25<>"",VLOOKUP(A25,項目仕様!$A$6:$L$129,3),"") | BA25: =IF(BB25&BC25<>"",MAX(BA$5:BA24)+1,"")
C26: =IF(A26<>"",VLOOKUP(A26,項目仕様!$A$6:$L$129,3),"") | V26: 2.2 | X26: フォーカスを明細の1行目のセットする | BA26: =IF(BB26&BC26<>"",MAX(BA$5:BA25)+1,"") -> 5 | BB26: 正・単
C27: =IF(A27<>"",VLOOKUP(A27,項目仕様!$A$6:$L$129,3),"") | BA27: =IF(BB27&BC27<>"",MAX(BA$5:BA26)+1,"")
A28: 3 | C28: =IF(A28<>"",VLOOKUP(A28,項目仕様!$A$6:$L$129,3),"") -> 無効を含む | L28: 無効を含むチェックボックスを選択 | U28: 1 | W28: 無効を含むチェックがＴＲＵＥの場合 | BA28: =IF(BB28&BC28<>"",MAX(BA$5:BA27)+1,"")
C29: =IF(A29<>"",VLOOKUP(A29,項目仕様!$A$6:$L$129,3),"") | V29: 1.1 | X29: ログインユーザ情報をログインユーザマスタから取得し、ログインユーザ情報一覧にセットする | AX29: SQLID： | AY29: S1 | BA29: =IF(BB29&BC29<>"",MAX(BA$5:BA28)+1,"") -> 6 | BB29: 正・単
C30: =IF(A30<>"",VLOOKUP(A30,項目仕様!$A$6:$L$129,3),"") | Y30: 引数.無効を含む＝True | BA30: =IF(BB30&BC30<>"",MAX(BA$5:BA29)+1,"")
C31: =IF(A31<>"",VLOOKUP(A31,項目仕様!$A$6:$L$129,3),"") | BA31: =IF(BB31&BC31<>"",MAX(BA$5:BA30)+1,"")
C32: =IF(A32<>"",VLOOKUP(A32,項目仕様!$A$6:$L$129,3),"") | U32: 2 | W32: 無効を含むチェックがFALSEの場合 | BA32: =IF(BB32&BC32<>"",MAX(BA$5:BA31)+1,"")
C33: =IF(A33<>"",VLOOKUP(A33,項目仕様!$A$6:$L$129,3),"") | V33: 2.1 | X33: ログインユーザ情報をログインユーザマスタから取得し、ログインユーザ情報一覧にセットする | AX33: SQLID： | AY33: S1 | BA33: =IF(BB33&BC33<>"",MAX(BA$5:BA32)+1,"") -> 7 | BB33: 正・単
C34: =IF(A34<>"",VLOOKUP(A34,項目仕様!$A$6:$L$129,3),"") | Y34: 引数.無効を含む＝False | BA34: =IF(BB34&BC34<>"",MAX(BA$5:BA33)+1,"")
C35: =IF(A35<>"",VLOOKUP(A35,項目仕様!$A$6:$L$129,3),"") | BA35: =IF(BB35&BC35<>"",MAX(BA$5:BA34)+1,"")
C36: =IF(A36<>"",VLOOKUP(A36,項目仕様!$A$6:$L$129,3),"") | U36: 3 | W36: フォーカスを明細の1行目のセットする | BA36: =IF(BB36&BC36<>"",MAX(BA$5:BA35)+1,"") -> 8 | BB36: 正・単
C37: =IF(A37<>"",VLOOKUP(A37,項目仕様!$A$6:$L$129,3),"") | BA37: =IF(BB37&BC37<>"",MAX(BA$5:BA36)+1,"")
A38: 4 | C38: =IF(A38<>"",VLOOKUP(A38,項目仕様!$A$6:$L$129,3),"") -> 【ログイン情報一覧】 | L38: ログイン情報一覧の行を | U38: 1 | W38: 行クリック、ダブルクリックの場合 | BA38: =IF(BB38&BC38<>"",MAX(BA$5:BA37)+1,"")
C39: =IF(A39<>"",VLOOKUP(A39,項目仕様!$A$6:$L$129,3),"") | L39: クリック、ダブルクリック | V39: 1.1 | X39: クリック行のの情報をログイン情報にセット表示する | BA39: =IF(BB39&BC39<>"",MAX(BA$5:BA38)+1,"") -> 9 | BB39: 正・単
C40: =IF(A40<>"",VLOOKUP(A40,項目仕様!$A$6:$L$129,3),"") | Y40: 画面.ログイン情報.方面担当 | AJ40: ← | AL40: 画面.グリット情報.方面担当 | BA40: =IF(BB40&BC40<>"",MAX(BA$5:BA39)+1,"") -> 10 | BB40: 正・単
C41: =IF(A41<>"",VLOOKUP(A41,項目仕様!$A$6:$L$129,3),"") | Y41: 画面.ログイン情報.ログイン名 | AJ41: ← | AL41: 画面.グリット情報.ログイン名 | BA41: =IF(BB41&BC41<>"",MAX(BA$5:BA40)+1,"") -> 11 | BB41: 正・単
...

Sheet SQL詳細仕様
A1: 【SQL詳細仕様】 | K1: 顧客名 / プロジェクト名 | V1: システム名 / サブシステム名 | AG1: 機能ID / 機能名 | BD1: 合計項目数 | BE1: 初回合格数 | BF1: 初回不合格数 | BG1: 未処理数
K2: =表紙!K2 -> BQ | V2: =表紙!V2 -> 受講管理システム | AG2: =表紙!AG2 -> BJ990100E | BD2: =COUNTA(BB6:BB112) -> 15 | BE2: =COUNTIF(BF6:BF112,"○") -> 15 | BF2: =COUNTIF(BF6:BF112,"×") -> 0 | BG2: =BD2 - COUNTIF(BG6:BG112,">=1900/1/1") -> 0
K3: =表紙!K3 -> BJ | V3: =表紙!V3 -> マスタメンテナンス | AG3: =表紙!AG3 -> ログインユーザマスタ管理
A5: SQLID | C5: 分類 | F5: クエリ仕様 | AG5: 補足 | BA5: № | BB5: 四象限 | BC5: 補足 | BD5: 試験日 | BE5: 試験者 | BF5: 合否 | BG5: 完了日付
A6: S1 | C6: Select | F6: ◆ログインユーザ情報取得 | BA6: =IF(BB6&BC6<>"",MAX(BA$5:BA5)+1,"")
BA7: =IF(BB7&BC7<>"",MAX(BA$5:BA6)+1,"")
F8: 取得項目 | BA8: =IF(BB8&BC8<>"",MAX(BA$5:BA7)+1,"")
G9: ① | H9: 方面ID | BA9: =IF(BB9&BC9<>"",MAX(BA$5:BA8)+1,"") -> 1 | BB9: 正・単 | BD9: 42685 | BE9: NPC中田 | BF9: ○ | BG9: 42685
G10: ② | H10: 方面担当 | BA10: =IF(BB10&BC10<>"",MAX(BA$5:BA9)+1,"") -> 2 | BB10: 正・単 | BD10: 42685 | BE10: NPC中田 | BF10: ○ | BG10: 42685
G11: ① | H11: ログインID | BA11: =IF(BB11&BC11<>"",MAX(BA$5:BA10)+1,"") -> 3 | BB11: 正・単 | BD11: 42685 | BE11: NPC中田 | BF11: ○ | BG11: 42685
G12: ① | H12: ログイン名 | BA12: =IF(BB12&BC12<>"",MAX(BA$5:BA11)+1,"") -> 4 | BB12: 正・単 | BD12: 42685 | BE12: NPC中田 | BF12: ○ | BG12: 42685
G13: ① | H13: 権限区分 | BA13: =IF(BB13&BC13<>"",MAX(BA$5:BA12)+1,"") -> 5 | BB13: 正・単 | BD13: 42685 | BE13: NPC中田 | BF13: ○ | BG13: 42685
G14: ③ | H14: 権限区分名 | BA14: =IF(BB14&BC14<>"",MAX(BA$5:BA13)+1,"") -> 6 | BB14: 正・単 | BD14: 42685 | BE14: NPC中田 | BF14: ○ | BG14: 42685
H15: CASE WHEN 権限区分 = '0' THEN 'システム管理者' | BA15: =IF(BB15&BC15<>"",MAX(BA$5:BA14)+1,"") -> 7 | BB15: 正・単 | BD15: 42685 | BE15: NPC中田 | BF15: ○ | BG15: 42685
I16: WHEN 権限区分 = '1' THEN '協会本部' | BA16: =IF(BB16&BC16<>"",MAX(BA$5:BA15)+1,"")
I17: WHEN 権限区分 = '3' THEN '方面本部' | BA17: =IF(BB17&BC17<>"",MAX(BA$5:BA16)+1,"")
H18: ELSE '' END | BA18: =IF(BB18&BC18<>"",MAX(BA$5:BA17)+1,"")
G19: ① | H19: パスワード | BA19: =IF(BB19&BC19<>"",MAX(BA$5:BA18)+1,"") -> 8 | BB19: 正・単 | BD19: 42685 | BE19: NPC中田 | BF19: ○ | BG19: 42685
G20: ① | H20: パスワード変更日 | BA20: =IF(BB20&BC20<>"",MAX(BA$5:BA19)+1,"") -> 9 | BB20: 正・単 | BD20: 42685 | BE20: NPC中田 | BF20: ○ | BG20: 42685
G21: ① | H21: 削除フラグ | BA21: =IF(BB21&BC21<>"",MAX(BA$5:BA20)+1,"") -> 10 | BB21: 正・単 | BD21: 42685 | BE21: NPC中田 | BF21: ○ | BG21: 42685
G22: ① | H22: 登録担当者 | BA22: =IF(BB22&BC22<>"",MAX(BA$5:BA21)+1,"") -> 11 | BB22: 正・単 | BD22: 42685 | BE22: NPC中田 | BF22: ○ | BG22: 42685
G23: ① | H23: 登録日 | BA23: =IF(BB23&BC23<>"",MAX(BA$5:BA22)+1,"") -> 12 | BB23: 正・単 | BD23: 42685 | BE23: NPC中田 | BF23: ○ | BG23: 42685
G24: ① | H24: 更新担当者 | BA24: =IF(BB24&BC24<>"",MAX(BA$5:BA23)+1,"") -> 13 | BB24: 正・単 | BD24: 42685 | BE24: NPC中田 | BF24: ○ | BG24: 42685
G25: ① | H25: 更新日 | BA25: =IF(BB25&BC25<>"",MAX(BA$5:BA24)+1,"") -> 14 | BB25: 正・単 | BD25: 42685 | BE25: NPC中田 | BF25: ○ | BG25: 42685
BA26: =IF(BB26&BC26<>"",MAX(BA$5:BA25)+1,"")
F27: 参照テーブル | BA27: =IF(BB27&BC27<>"",MAX(BA$5:BA26)+1,"")
G28: ①ログインユーザマスタ | BA28: =IF(BB28&BC28<>"",MAX(BA$5:BA27)+1,"")
G29: ②方面マスタ | Q29: LEFT JOIN 条件 | V29: ①方面ID ＝ ②方面ID | BA29: =IF(BB29&BC29<>"",MAX(BA$5:BA28)+1,"")
V30: ②削除フラグ≠'1'
F31: 条件 | I31: ※すべてAND | BA31: =IF(BB31&BC31<>"",MAX(BA$5:BA30)+1,"")
G32: 引数.無効フラグ＝False の場合 | BA32: =IF(BB32&BC32<>"",MAX(BA$5:BA31)+1,"")
H33: ①削除フラグ≠'1' | BA33: =IF(BB33&BC33<>"",MAX(BA$5:BA32)+1,"")
BA34: =IF(BB34&BC34<>"",MAX(BA$5:BA33)+1,"")
F35: 並び順 | BA35: =IF(BB35&BC35<>"",MAX(BA$5:BA34)+1,"")
G36: ログインID | BA36: =IF(BB36&BC36<>"",MAX(BA$5:BA35)+1,"")
BA37: =IF(BB37&BC37<>"",MAX(BA$5:BA36)+1,"")
A38: S2 | C38: Select | F38: ◆ログインユーザID件数取得 | BA38: =IF(BB38&BC38<>"",MAX(BA$5:BA37)+1,"")
BA39: =IF(BB39&BC39<>"",MAX(BA$5:BA38)+1,"")
F40: 取得項目 | BA40: =IF(BB40&BC40<>"",MAX(BA$5:BA39)+1,"")
G41: ① | H41: 件数 | BA41: =IF(BB41&BC41<>"",MAX(BA$5:BA40)+1,"") -> 15 | BB41: 正・単 | BD41: 42685 | BE41: NPC中田 | BF41: ○ | BG41: 42685
...

Sheet 機能シート
C2: ：現在のブック内の「画面項目説明」シートを元に新規シート「画面項目テスト仕様書」を作成します。既存の作成結果は「画面項目テスト仕様書第n版」に変更されます。
C5: ：このオプションを選択すると、テスト項目の無いテスト内容欄に「 - 」が挿入されます。
C7: ：このオプションを選択すると、テスト項目の有無に関わらずテスト内容欄は空欄になります。
B9: 注：これより下の部分は仕様書の構成に関わる設定です。この仕様書作成マクロは、以下の設定を見て動いています。
B10: 仕様書の構成を変更する際には「画面項目説明」シートの構成を変更した後、細心の注意を払って以下の部分を変更してください。
B12: No | D12: 項目のナンバーが振られているセルのヘッダ名
B14: 説明 | C14: 内容 | D14: 仕様書になると二段に増える備考部分ヘッダ名と、二段目の名称
B16: I/O | D16: 「▼項目」カテゴリ内で、テスト内容欄最も左端の欄のヘッダ名
B18: 説明 | D18: 「▼項目」カテゴリ内で、テスト内容欄最も右端の欄のヘッダ名
B20: 画面 又は | D20: 「▼出力項目」カテゴリ内で、テスト内容欄最も左端の欄のヘッダ名
D21: （二列のうち片方でよい）
B22: セット方法、またはフォーマット等 | D22: 「▼出力項目」カテゴリ内で、テスト内容欄最も右端のヘッダ名
D23: (現状変更未対応に等しい状態です……）
B24: セット方法、 | C24: またはフォーマット等 | D24: 上のヘッダ名が二段に分かれた際の分け方
D25: （同上）
